Workbook

Sheet AllSorges 2 NL No Legend Order2
A1: Sample | B1: D | C1: O | D1: Sp | E1: Cond | F1: Order | G1: Year | J1: Conditions Total | L1: MeanO | M1: MeanH | N1: Error O | O1: Error H
A2: S-FO-1 | B2: -98.797599 | C2: 24.340408 | D2: Fraxinus | E2: Living | F2: 0 | G2: 1 | J2: Living Frax | L2: =+AVERAGE(C2:C11) -> 23.842154 | M2: =+AVERAGE(B2:B11) -> -99.352843 | N2: =+STDEV(C2:C11)/SQRT(COUNT(C2:C11)) -> 0.30397237 | O2: =+STDEV(B2:B11)/SQRT(COUNT(B2:B11)) -> 1.9230323
A3: S-FO-2 | B3: -95.081829 | C3: 22.504079 | D3: Fraxinus | E3: Living | F3: 0 | G3: 2 | J3: Living Frax
A4: S-FO-3 | B4: -101.31614 | C4: 23.972102 | D4: Fraxinus | E4: Living | F4: 0 | G4: 3 | J4: Living Frax
A5: S-FO-4 | B5: -92.26319 | C5: 23.965859 | D5: Fraxinus | E5: Living | F5: 0 | G5: 4 | J5: Living Frax
A6: S-FO-5 | B6: -106.67558 | C6: 22.631009 | D6: Fraxinus | E6: Living | F6: 0 | G6: 5 | J6: Living Frax
A7: S-FO-6 | B7: -93.812487 | C7: 23.94401 | D7: Fraxinus | E7: Living | F7: 0 | G7: 6 | J7: Living Frax
A8: S-FO-7 | B8: -105.97251 | C8: 24.425722 | D8: Fraxinus | E8: Living | F8: 0 | G8: 7 | J8: Living Frax
A9: S-FO-8 | B9: -102.34476 | C9: 22.777707 | D9: Fraxinus | E9: Living | F9: 0 | G9: 8 | J9: Living Frax
A10: S-FO-9 | B10: -90.820996 | C10: 25.610752 | D10: Fraxinus | E10: Living | F10: 0 | G10: 9 | J10: Living Frax
A11: S-FO-10 | B11: -106.44335 | C11: 24.249892 | D11: Fraxinus | E11: Living | F11: 0 | G11: 10 | J11: Living Frax
A12: S-F1-F-1 | B12: -86.605761 | C12: 25.678379 | D12: Fraxinus | E12: Float | F12: 1 | G12: 1 | J12: In-channel Frax | L12: =+AVERAGE(C12:C21) -> 23.269846 | M12: =+AVERAGE(B12:B21) -> -81.694286 | N12: =+STDEV(C12:C21)/SQRT(COUNT(C12:C21)) -> 0.54863077 | O12: =+STDEV(B12:B21)/SQRT(COUNT(B12:B21)) -> 1.8964766
A13: S-F1-F-2 | B13: -83.32159 | C13: 23.467501 | D13: Fraxinus | E13: Float | F13: 1 | G13: 2 | J13: In-channel Frax
A14: S-F1-F-3 | B14: -77.061834 | C14: 21.166107 | D14: Fraxinus | E14: Float | F14: 1 | G14: 3 | J14: In-channel Frax
A15: S-F1-F-4 | B15: -73.535883 | C15: 20.807165 | D15: Fraxinus | E15: Float | F15: 1 | G15: 4 | J15: In-channel Frax
A16: S-F1-F-5 | B16: -83.537919 | C16: 23.241732 | D16: Fraxinus | E16: Float | F16: 1 | G16: 5 | J16: In-channel Frax
A17: S-F1-F-6 | B17: -74.877335 | C17: 21.371069 | D17: Fraxinus | E17: Float | F17: 1 | G17: 6 | J17: In-channel Frax
A18: S-F1-F-7 | B18: -76.683258 | C18: 23.804595 | D18: Fraxinus | E18: Float | F18: 1 | G18: 7 | J18: In-channel Frax
A19: S-F1-F-8 | B19: -86.112658 | C19: 23.141852 | D19: Fraxinus | E19: Float | F19: 1 | G19: 8 | J19: In-channel Frax
A20: S-F1-F-9 | B20: -82.882569 | C20: 24.379944 | D20: Fraxinus | E20: Float | F20: 1 | G20: 9 | J20: In-channel Frax
A21: S-F1-F-10 | B21: -92.324055 | C21: 25.640119 | D21: Fraxinus | E21: Float | F21: 1 | G21: 10 | J21: In-channel Frax
A22: S-F1-E-1 | B22: -91.113037 | C22: 25.911667 | D22: Fraxinus | E22: Out | F22: 1 | G22: 1 | J22: Floodplain Frax | K22: April.21 | L22: =+AVERAGE(C22:C31) -> 23.857992 | M22: =+AVERAGE(B22:B31) -> -87.18299 | N22: =+STDEV(C22:C31)/SQRT(COUNT(C22:C31)) -> 0.37422537 | O22: =+STDEV(B22:B31)/SQRT(COUNT(B22:B31)) -> 1.7132716
A23: S-F1-E-2 | B23: -88.372448 | C23: 23.176185 | D23: Fraxinus | E23: Out | F23: 1 | G23: 2 | J23: Floodplain Frax
A24: S-F1-E-3 | B24: -85.417012 | C24: 21.959942 | D24: Fraxinus | E24: Out | F24: 1 | G24: 3 | J24: Floodplain Frax
A25: S-F1-E-4 | B25: -78.793526 | C25: 23.355137 | D25: Fraxinus | E25: Out | F25: 1 | G25: 4 | J25: Floodplain Frax
A26: S-F1-E-5 | B26: -79.038487 | C26: 23.683907 | D26: Fraxinus | E26: Out | F26: 1 | G26: 5 | J26: Floodplain Frax
A27: S-F1-E-6 | B27: -85.361869 | C27: 23.74217 | D27: Fraxinus | E27: Out | F27: 1 | G27: 6 | J27: Floodplain Frax
A28: S-F1-E-7 | B28: -85.165689 | C28: 25.749127 | D28: Fraxinus | E28: Out | F28: 1 | G28: 7 | J28: Floodplain Frax
A29: S-F1-E-8 | B29: -91.318341 | C29: 23.332247 | D29: Fraxinus | E29: Out | F29: 1 | G29: 8 | J29: Floodplain Frax
A30: S-F1-E-9 | B30: -93.588735 | C30: 23.544492 | D30: Fraxinus | E30: Out | F30: 1 | G30: 9 | J30: Floodplain Frax
A31: S-F1-E-10 | B31: -93.66076 | C31: 24.125042 | D31: Fraxinus | E31: Out | F31: 1 | G31: 10 | J31: Floodplain Frax
A32: S-F1-S-1 | B32: -70.525725 | C32: 22.852852 | D32: Fraxinus | E32: Sub | F32: 1 | G32: 1 | J32: Submerged Frax | L32: =+AVERAGE(C32:C41) -> 24.526357 | M32: =+AVERAGE(B32:B41) -> -81.840687 | N32: =+STDEV(C32:C41)/SQRT(COUNT(C32:C41)) -> 0.83140261 | O32: =+STDEV(B32:B41)/SQRT(COUNT(B32:B41)) -> 2.4044216
A33: S-F1-S-2 | B33: -82.114174 | C33: 24.072217 | D33: Fraxinus | E33: Sub | F33: 1 | G33: 2 | J33: Submerged Frax
A34: S-F1-S-3 | B34: -78.48536 | C34: 22.709275 | D34: Fraxinus | E34: Sub | F34: 1 | G34: 3 | J34: Submerged Frax
A35: S-F1-S-4 | B35: -71.029432 | C35: 21.362981 | D35: Fraxinus | E35: Sub | F35: 1 | G35: 4 | J35: Submerged Frax
A36: S-F1-S-5 | B36: -84.498035 | C36: 24.636121 | D36: Fraxinus | E36: Sub | F36: 1 | G36: 5 | J36: Submerged Frax | BC36: xxxx
A37: S-F1-S-6 | B37: -80.881947 | C37: 22.801872 | D37: Fraxinus | E37: Sub | F37: 1 | G37: 6 | J37: Submerged Frax
A38: S-F1-S-7 | B38: -80.284921 | C38: 24.034762 | D38: Fraxinus | E38: Sub | F38: 1 | G38: 7 | J38: Submerged Frax
A39: S-F1-S-8 | B39: -91.355877 | C39: 26.309105 | D39: Fraxinus | E39: Sub | F39: 1 | G39: 8 | J39: Submerged Frax
A40: S-F1-S-9 | B40: -85.02083 | C40: 25.805545 | D40: Fraxinus | E40: Sub | F40: 1 | G40: 9 | J40: Submerged Frax
...

Sheet AllSorgesMean
A1: Sample | B1: d18O VSMOW | C1: d2H VSMOW | D1: Sp | E1: Year | F1: Cond | G1: Order | I1: MeanO | J1: MeanH | K1: Error O | L1: Error H | M1: TotalErrorO | N1: TotalErrorH | O1: MaxO | P1: MinO | Q1: MaxH | R1: MinH
A2: S-FO-1 | B2: 24.340408 | C2: -98.797599 | D2: Fraxinus | E2: 1 | F2: Living Dic 20 | G2: 0 | I2: 23.842154 | J2: -99.352843 | K2: 0.30397237 | L2: 1.9230323 | O2: 0 | P2: =I2+MAX(K2,K3,K4,K5,K10,K11,K12,K13,K16,K17,K18,K25,K26,K29,K30,K33,K34,K37)-MIN(I2,I3,I4,I5,I10,I11,I12,I13,I16,I17,I18,I25,I26,I29,I30,I33,I34,I37) -> 4.0587058 | Q2: =+MAX(J2,J3,J4,J5,J10,J11,J12,J13,J16,J17,J18,J25,J26,J29,J30,J33,J34,J37)+MAX(L2,L3,L4,L5,L10,L11,L12,L13,L16,L17,L18,L25,L26,L29,L30,L33,L34,L37)-J2 -> 22.186844 | R2: =J2+MAX(L2,L3,L4,L5,L10,L11,L12,L13,L16,L17,L18,L25,L26,L29,L30,L33,L34,L37)-MIN(J2,J3,J4,J5,J10,J11,J12,J13,J16,J17,J18,J25,J26,J29,J30,J33,J34,J37) -> 6.1984564 | U2: Floating (instream)
A3: S-F1-F-1 | B3: 25.678379 | C3: -86.605761 | D3: Fraxinus | E3: 1 | F3: Float | G3: 1 | I3: 23.269846 | J3: -81.694286 | K3: 0.54863077 | L3: 1.8964766 | U3: Floodplain (outside)
A4: S-F1-E-1 | B4: 24.911667 | C4: -91.113037 | D4: Fraxinus | E4: 1 | F4: Out | G4: 1 | H4: April.21 | I4: 23.857992 | J4: -87.18299 | K4: 0.37422537 | L4: 1.7132716 | U4: Floating (instream)
A5: S-F1-S-1 | B5: 21.852852 | C5: -70.525725 | D5: Fraxinus | E5: 1 | F5: Sub | G5: 1 | I5: 24.526357 | J5: -81.840687 | K5: 0.83140261 | L5: 2.4044216 | U5: Floodplain (outside)
A6: S-AO-1 | B6: 21.173227 | C6: -108.09231 | D6: Alnus | E6: 1 | F6: Living Dic20 | G6: 0 | I6: 21.77787 | J6: -102.54454 | K6: 0.21776401 | L6: 1.1951 | M6: =-MIN(AllSorgesMean!$I$6,AllSorgesMean!$I$7,AllSorgesMean!$I$14,AllSorgesMean!$I$20,AllSorgesMean!$I$21,AllSorgesMean!$I$24,AllSorgesMean!$I$28,AllSorgesMean!$I$32,AllSorgesMean!$I$36, AllSorgesMean!$I$6,AllSorgesMean!$I$8,AllSorgesMean!$I$15,AllSorgesMean!$I$19,AllSorgesMean!$I$22,AllSorgesMean!$I$23,AllSorgesMean!$I$27,AllSorgesMean!$I$31,AllSorgesMean!$I$35) - MAX( AllSorgesMean!$K$6,AllSorgesMean!$K$7,AllSorgesMean!$K$14,AllSorgesMean!$K$20,AllSorgesMean!$K$21,AllSorgesMean!$K$24,AllSorgesMean!$K$28,AllSorgesMean!$K$32,AllSorgesMean!$K$36, AllSorgesMean!$K$6,AllSorgesMean!$K$8,AllSorgesMean!$K$15,AllSorgesMean!$K$19,AllSorgesMean!$K$22,AllSorgesMean!$K$23,AllSorgesMean!$K$27,AllSorgesMean!$K$31,AllSorgesMean!$K$35)+ MAX(AllSorgesMean!$I$6,AllSorgesMean!$I$7,AllSorgesMean!$I$14,AllSorgesMean!$I$20,AllSorgesMean!$I$21,AllSorgesMean!$I$24,AllSorgesMean!$I$28,AllSorgesMean!$I$32,AllSorgesMean!$I$36, AllSorgesMean!$I$6,AllSorgesMean!$I$8,AllSorgesMean!$I$15,AllSorgesMean!$I$19,AllSorgesMean!$I$22,AllSorgesMean!$I$23,AllSorgesMean!$I$27,AllSorgesMean!$I$31,AllSorgesMean!$I$35) + MAX( AllSorgesMean!$K$6,AllSorgesMean!$K$7,AllSorgesMean!$K$14,AllSorgesMean!$K$20,AllSorgesMean!$K$21,AllSorgesMean!$K$24,AllSorgesMean!$K$28,AllSorgesMean!$K$32,AllSorgesMean!$K$36, AllSorgesMean!$K$6,AllSorgesMean!$K$8,AllSorgesMean!$K$15,AllSorgesMean!$K$19,AllSorgesMean!$K$22,AllSorgesMean!$K$23,AllSorgesMean!$K$27,AllSorgesMean!$K$31,AllSorgesMean!$K$35) -> 4.5785242 | N6: =+MAX(AllSorgesMean!$J$6,AllSorgesMean!$J$7,AllSorgesMean!$J$14,AllSorgesMean!$J$20,AllSorgesMean!$J$21,AllSorgesMean!$J$24,AllSorgesMean!$J$28,AllSorgesMean!$J$32,AllSorgesMean!$J$36, AllSorgesMean!$J$6,AllSorgesMean!$J$8,AllSorgesMean!$J$15,AllSorgesMean!$J$19,AllSorgesMean!$J$22,AllSorgesMean!$J$23,AllSorgesMean!$J$27,AllSorgesMean!$J$31,AllSorgesMean!$J$35) +MAX(AllSorgesMean!$L$6,AllSorgesMean!$L$7,AllSorgesMean!$L$14,AllSorgesMean!$L$20,AllSorgesMean!$L$21,AllSorgesMean!$L$24,AllSorgesMean!$L$28,AllSorgesMean!$L$32,AllSorgesMean!$L$36, AllSorgesMean!$L$6,AllSorgesMean!$L$8,AllSorgesMean!$L$15,AllSorgesMean!$L$19,AllSorgesMean!$L$22,AllSorgesMean!$L$23,AllSorgesMean!$L$27,AllSorgesMean!$L$31,AllSorgesMean!$L$35) -MIN(AllSorgesMean!$J$6,AllSorgesMean!$J$7,AllSorgesMean!$J$14,AllSorgesMean!$J$20,AllSorgesMean!$J$21,AllSorgesMean!$J$24,AllSorgesMean!$J$28,AllSorgesMean!$J$32,AllSorgesMean!$J$36, AllSorgesMean!$J$6,AllSorgesMean!$J$8,AllSorgesMean!$J$15,AllSorgesMean!$J$19,AllSorgesMean!$J$22,AllSorgesMean!$J$23,AllSorgesMean!$J$27,AllSorgesMean!$J$31,AllSorgesMean!$J$35) - MAX( AllSorgesMean!$L$6,AllSorgesMean!$L$7,AllSorgesMean!$L$14,AllSorgesMean!$L$20,AllSorgesMean!$L$21,AllSorgesMean!$L$24,AllSorgesMean!$L$28,AllSorgesMean!$L$32,AllSorgesMean!$L$36, AllSorgesMean!$L$6,AllSorgesMean!$L$8,AllSorgesMean!$L$15,AllSorgesMean!$L$19,AllSorgesMean!$L$22,AllSorgesMean!$L$23,AllSorgesMean!$L$27,AllSorgesMean!$L$31,AllSorgesMean!$L$35) -> 16.293296 | O6: =+MAX(AllSorgesMean!$I$6,AllSorgesMean!$I$7,AllSorgesMean!$I$14,AllSorgesMean!$I$20,AllSorgesMean!$I$21,AllSorgesMean!$I$24,AllSorgesMean!$I$28,AllSorgesMean!$I$32,AllSorgesMean!$I$36, AllSorgesMean!$I$6,AllSorgesMean!$I$8,AllSorgesMean!$I$15,AllSorgesMean!$I$19,AllSorgesMean!$I$22,AllSorgesMean!$I$23,AllSorgesMean!$I$27,AllSorgesMean!$I$31,AllSorgesMean!$I$35) + MAX( $K$6,AllSorgesMean!$K$7,AllSorgesMean!$K$14,AllSorgesMean!$K$20,AllSorgesMean!$K$21,AllSorgesMean!$K$24,AllSorgesMean!$K$28,AllSorgesMean!$K$32,AllSorgesMean!$K$36, AllSorgesMean!$K$6,AllSorgesMean!$K$8,AllSorgesMean!$K$15,AllSorgesMean!$K$19,AllSorgesMean!$K$22,AllSorgesMean!$K$23,AllSorgesMean!$K$27,AllSorgesMean!$K$31,AllSorgesMean!$K$35)-I6 -> 2.2871475 | P6: =-MIN(AllSorgesMean!$I$6,AllSorgesMean!$I$7,AllSorgesMean!$I$14,AllSorgesMean!$I$20,AllSorgesMean!$I$21,AllSorgesMean!$I$24,AllSorgesMean!$I$28,AllSorgesMean!$I$32,AllSorgesMean!$I$36, AllSorgesMean!$I$6,AllSorgesMean!$I$8,AllSorgesMean!$I$15,AllSorgesMean!$I$19,AllSorgesMean!$I$22,AllSorgesMean!$I$23,AllSorgesMean!$I$27,AllSorgesMean!$I$31,AllSorgesMean!$I$35) + MAX( AllSorgesMean!$K$6,AllSorgesMean!$K$7,AllSorgesMean!$K$14,AllSorgesMean!$K$20,AllSorgesMean!$K$21,AllSorgesMean!$K$24,AllSorgesMean!$K$28,AllSorgesMean!$K$32,AllSorgesMean!$K$36, AllSorgesMean!$K$6,AllSorgesMean!$K$8,AllSorgesMean!$K$15,AllSorgesMean!$K$19,AllSorgesMean!$K$22,AllSorgesMean!$K$23,AllSorgesMean!$K$27,AllSorgesMean!$K$31,AllSorgesMean!$K$35)+I6 -> 2.9282774 | Q6: =++MAX(AllSorgesMean!$J$6,AllSorgesMean!$J$7,AllSorgesMean!$J$14,AllSorgesMean!$J$20,AllSorgesMean!$J$21,AllSorgesMean!$J$24,AllSorgesMean!$J$28,AllSorgesMean!$J$32,AllSorgesMean!$J$36, AllSorgesMean!$J$6,AllSorgesMean!$J$8,AllSorgesMean!$J$15,AllSorgesMean!$J$19,AllSorgesMean!$J$22,AllSorgesMean!$J$23,AllSorgesMean!$J$27,AllSorgesMean!$J$31,AllSorgesMean!$J$35) +MAX(AllSorgesMean!$L$6,AllSorgesMean!$L$7,AllSorgesMean!$L$14,AllSorgesMean!$L$20,AllSorgesMean!$L$21,AllSorgesMean!$L$24,AllSorgesMean!$L$28,AllSorgesMean!$L$32,AllSorgesMean!$L$36, AllSorgesMean!$L$6,AllSorgesMean!$L$8,AllSorgesMean!$L$15,AllSorgesMean!$L$19,AllSorgesMean!$L$22,AllSorgesMean!$L$23,AllSorgesMean!$L$27,AllSorgesMean!$L$31,AllSorgesMean!$L$35)-J6 -> 9.8064091 | R6: =+J6-MIN(AllSorgesMean!$J$6,AllSorgesMean!$J$7,AllSorgesMean!$J$14,AllSorgesMean!$J$20,AllSorgesMean!$J$21,AllSorgesMean!$J$24,AllSorgesMean!$J$28,AllSorgesMean!$J$32,AllSorgesMean!$J$36, AllSorgesMean!$J$6,AllSorgesMean!$J$8,AllSorgesMean!$J$15,AllSorgesMean!$J$19,AllSorgesMean!$J$22,AllSorgesMean!$J$23,AllSorgesMean!$J$27,AllSorgesMean!$J$31,AllSorgesMean!$J$35) + MAX( AllSorgesMean!$L$6,AllSorgesMean!$L$7,AllSorgesMean!$L$14,AllSorgesMean!$L$20,AllSorgesMean!$L$21,AllSorgesMean!$L$24,AllSorgesMean!$L$28,AllSorgesMean!$L$32,AllSorgesMean!$L$36, AllSorgesMean!$L$6,AllSorgesMean!$L$8,AllSorgesMean!$L$15,AllSorgesMean!$L$19,AllSorgesMean!$L$22,AllSorgesMean!$L$23,AllSorgesMean!$L$27,AllSorgesMean!$L$31,AllSorgesMean!$L$35) -> 12.265744
A7: S-A1-F-1 | B7: 22.590342 | C7: -101.18076 | D7: Alnus | E7: 1 | F7: Float | G7: 1 | H7: April.21 | I7: 23.14724 | J7: -100.8664 | K7: 0.16037644 | L7: 1.1705154
A8: S-A1-E-1 | B8: 23.43324 | C8: -104.7248 | D8: Alnus | E8: 1 | F8: Out | G8: 1 | H8: April.21 | I8: 23.746567 | J8: -99.239585 | K8: 0.23116484 | L8: 0.90617656
A9: S-A1-S-1 | B9: 22.612354 | C9: -103.01538 | D9: Alnus | E9: 1 | F9: Sub | G9: 1 | I9: 22.705218 | J9: -102.24486 | K9: 0.25134107 | L9: 1.0934327
A10: S-Sept21-F.F-1 | B10: 21.869362 | C10: -86.389375 | D10: Fraxinus | E10: 1 | F10: Float | G10: 2 | H10: Sept.21 | I10: 21.820678 | J10: -90.372491 | K10: 0.2332801 | L10: 2.1413989
A11: S-Sept21-F.O-1 | B11: 23.318 | C11: -90.668687 | D11: Fraxinus | E11: 1 | F11: Out | G11: 2 | I11: 22.068055 | J11: -81.366406 | K11: 0.27504668 | L11: 1.1106259
A12: S-Dic21-F.E-1 | B12: 20.960224 | C12: -92.100613 | D12: Fraxinus | E12: 1 | F12: Out | G12: 3 | H12: Dic.21 | I12: 22.0281 | J12: -97.698991 | K12: 0.21822789 | L12: 2.0573903
A13: SDic21-F.S-1 | B13: 21.81318 | C13: -81.52909 | D13: Fraxinus | E13: 1 | F13: Sub | G13: 3 | I13: 22.529088 | J13: -82.984983 | K13: 0.23145667 | L13: 2.034366
A14: S-Sept21-A.F-1 | B14: 20.443812 | C14: -93.752139 | D14: Alnus | E14: 1 | F14: Float | G14: 2 | H14: Sept.21 | I14: 21.256251 | J14: -98.249779 | K14: 0.23328994 | L14: 1.0997767
A15: S-Sept21-A.O-1 | B15: 20.342882 | C15: -103.90613 | D15: Alnus | E15: 1 | F15: Out | G15: 2 | H15: Sept.21 | I15: 20.805575 | J15: -102.04782 | K15: 0.14170982 | L15: 1.0369368
A16: S-Dic21-F.F-1 | B16: 22.699888 | C16: -84.61972 | D16: Fraxinus | E16: 1 | F16: Float | G16: 3 | I16: 22.174855 | J16: -84.056366 | K16: 0.24685102 | L16: 1.7294683
A17: S-May22-F.F-1 | B17: 21.053018 | C17: -79.446143 | D17: Fraxinus | E17: 1 | F17: Float | G17: 4 | H17: May.22 | I17: 22.170172 | J17: -84.87508 | K17: 0.28744524 | L17: 2.100148
A18: S-May22-F.E-1 | B18: 21.132179 | C18: -96.714913 | D18: Fraxinus | E18: 1 | F18: Out | G18: 4 | I18: 22.040942 | J18: -97.737716 | K18: 0.21885396 | L18: 1.7929544
A19: S-Dic21-A.S-1 | B19: 20.10628 | C19: -119.26415 | D19: Alnus | E19: 1 | F19: Out | G19: 3 | I19: 20.927472 | J19: -111.92085 | K19: 0.20435135 | L19: 0.79754472
A20: S-Dic21-A.F-1 | B20: 20.531878 | C20: -85.98076 | D20: Alnus | E20: 1 | F20: Float | G20: 3 | H20: Dic.21 | I20: 20.70801 | J20: -95.627555 | K20: 0.15130899 | L20: 1.1597326
A21: S-May22-A.F-1 | B21: 20.977046 | C21: -106.86858 | D21: Alnus | E21: 1 | F21: Float | G21: 4 | H21: May.22 | I21: 21.310411 | J21: -104.58521 | K21: 0.13276324 | L21: 1.1700964
A22: S-May22-A.O-1 | B22: 19.614385 | C22: -96.788441 | D22: Alnus | E22: 1 | F22: Out | G22: 4 | H22: May.22 | I22: 20.282698 | J22: -97.126068 | K22: 0.17355085 | L22: 0.67780757
A23: S-Dic22-A-O-1 | B23: 18.610322 | C23: -110.7059 | D23: Alnus | E23: 1 | F23: Out | G23: 5 | H23: Nov.22 | I23: 19.826295 | J23: -106.54949 | K23: 0.30327791 | L23: 2.8894285
A24: S-Dic22-A-F-1 | B24: 21.456178 | C24: -102.4311 | D24: Alnus | E24: 1 | F24: Float | G24: 5 | I24: 20.853057 | J24: -104.83581 | K24: 0.13376102 | L24: 1.2082924
A25: S-Dic22-F-O-1 | B25: 22.231349 | C25: -97.977748 | D25: Fraxinus | E25: 1 | F25: Out | G25: 5 | I25: 22.121183 | J25: -93.693347 | K25: 0.21543842 | L25: 2.7028187
A26: S-Dic22-F-F-1 | D26: Fraxinus | E26: 1 | F26: Float | G26: 5 | I26: 20.614851 | J26: -92.235106 | K26: 0.34305759 | L26: 2.7454205
A27: S-Aut23-A-O-1 | B27: 20.65696 | C27: -108.69557 | D27: Alnus | E27: 1 | F27: Out | G27: 6 | H27: May.23 | I27: 19.168043 | J27: -107.86597 | K27: 0.23954595 | L27: 2.4693252
A28: S-Aut23-A-F-1 | B28: 21.180142 | C28: -103.83557 | D28: Alnus | E28: 1 | F28: Float | G28: 6 | I28: 20.609184 | J28: -102.30186 | K28: 0.11419701 | L28: 1.0982142
A29: S-Aut23-F-O-1 | B29: 21.319171 | C29: -105.72117 | D29: Fraxinus | E29: 1 | F29: Out | G29: 6 | I29: 21.523983 | J29: -90.700701 | K29: 0.11715627 | L29: 2.9252879
A30: S-Aut23-F-F-1 | B30: 22.434952 | C30: -96.058535 | D30: Fraxinus | E30: 1 | F30: Float | G30: 6 | I30: 21.593933 | J30: -86.652909 | K30: 0.31093542 | L30: 2.0434797
A31: S-Dic23-A-O-1 | B31: 19.722154 | C31: -101.15639 | D31: Alnus | E31: 1 | F31: Out | G31: 7 | H31: Oct.23 | I31: 20.317823 | J31: -102.27085 | K31: 0.1179833 | L31: 0.84646667
A32: S-Dic23-A-F-1 | B32: 21.132816 | C32: -97.983024 | D32: Alnus | E32: 1 | F32: Float | G32: 7 | I32: 20.755021 | J32: -99.675269 | K32: 0.2598972 | L32: 1.6951292
A33: S-Dic23-F-O-1 | B33: 22.461673 | C33: -91.768892 | D33: Fraxinus | E33: 1 | F33: Out | G33: 7 | I33: 21.43951 | J33: -89.103566 | K33: 0.54815096 | L33: 3.5208158
A34: S-Dic23-F-F-1 | B34: 23.683768 | C34: -88.661873 | D34: Fraxinus | E34: 1 | F34: Float | G34: 7 | I34: 21.497191 | J34: -82.136817 | K34: 0.56774863 | L34: 4.2004067
A35: S-Feb24-A-O-1 | B35: 20.495605 | C35: -104.66697 | D35: Alnus | E35: 1 | F35: Out | G35: 8 | H35: Feb.24 | I35: 19.637002 | J35: -106.23601 | K35: 0.31845037 | L35: 1.4752904
A36: S-Feb24-A-F-1 | B36: 21.178098 | C36: -101.8917 | D36: Alnus | E36: 1 | F36: Float | G36: 8 | I36: 21.576256 | J36: -100.67817 | K36: 0.23421969 | L36: 1.4367348
A37: S-Feb24-F-O-1 | B37: 22.650272 | C37: -99.519584 | D37: Fraxinus | E37: 1 | F37: Out | G37: 8 | I37: 21.4405 | J37: -101.35089 | K37: 0.34796486 | L37: 2.163941
